Workbook

Sheet Activities
A1: Activities in the Program Assessment and Evaluation
A3: 1. Review the Program Learning Outcomes and the Performance Indicators
A4: 2. Gather all the courses of the program with attainment results of its learning outcomes (CLOs)
A5: 3. Map the CLOs to the specific PIs of the Program Learning Outcomes using the "I", "P", "D" mapping level
A6: 4. Fill in the Mapping sheet
A7: 5. Evaluate the results and fill in the PLO Attainment Evaluation sheet

Sheet CLO_Attainments
A1: Course Learning Outcomes (CLO) Attainment
A2: Batch 2022 to 2025
A3: ID No. | B3: Student Name | C3: CCC100 | F3: CCC101 | I3: CCC102 | L3: CCC121 | O3: CCC151 | R3: CCC181 | U3: CSC109 | X3: CSC112 | AA3: CSC113 | AD3: CSC124 | AG3: CSC130 | AJ3: CSC133 | AM3: CSC142 | AP3: CSC145 | AS3: CSC155 | AV3: CSC161 | AY3: CSC171 | BB3: CSC175 | BE3: CSC181 | BH3: CSC186 | BK3: CSC193 | BN3: Elective 1 (CSC153) | BQ3: Elective 2 (CSC172) | BT3: Elective 3 (CSC173) | BW3: CSC194 | BZ3: CSC197 | CC3: CSC198 | CF3: CSC199
C4: CLO 1 | D4: CLO 2 | E4: CLO 3 | F4: CLO 1 | G4: CLO 2 | H4: CLO 3 | I4: CLO 1 | J4: CLO 2 | K4: CLO 3 | L4: CLO 1 | M4: CLO 2 | N4: CLO 3 | O4: CLO 1 | P4: CLO 2 | Q4: CLO 3 | R4: CLO 1 | S4: CLO 2 | T4: CLO 3 | U4: CLO 1 | V4: CLO 2 | W4: CLO 3 | X4: CLO 1 | Y4: CLO 2 | Z4: CLO 3 | AA4: CLO 1 | AB4: CLO 2 | AC4: CLO 3 | AD4: CLO 1 | AE4: CLO 2 | AF4: CLO 3 | AG4: CLO 1 | AH4: CLO 2 | AI4: CLO 3 | AJ4: CLO 1 | AK4: CLO 2 | AL4: CLO 3 | AM4: CLO 1 | AN4: CLO 2 | AO4: CLO 3 | AP4: CLO 1 | AQ4: CLO 2 | AR4: CLO 3 | AS4: CLO 1 | AT4: CLO 2 | AU4: CLO 3 | AV4: CLO 1 | AW4: CLO 2 | AX4: CLO 3 | AY4: CLO 1 | AZ4: CLO 2 | BA4: CLO 3 | BB4: CLO 1 | BC4: CLO 2 | BD4: CLO 3 | BE4: CLO 1 | BF4: CLO 2 | BG4: CLO 3 | BH4: CLO 1 | BI4: CLO 2 | BJ4: CLO 3 | BK4: CLO 1 | BL4: CLO 2 | BM4: CLO 3 | BN4: CLO 1 | BO4: CLO 2 | BP4: CLO 3 | BQ4: CLO 1 | BR4: CLO 2 | BS4: CLO 3 | BT4: CLO 1 | BU4: CLO 2 | BV4: CLO 3 | BW4: CLO 1 | BX4: CLO 2 | BY4: CLO 3 | BZ4: CLO 1 | CA4: CLO 2 | CB4: CLO 3 | CC4: CLO 1 | CD4: CLO 2 | CE4: CLO 3 | CF4: CLO 1 | CG4: CLO 2 | CH4: CLO 3
A6: {=MAP(SEQUENCE(40,1), LAMBDA(x, "2050-" & TEXT(RANDBETWEEN(0, 9999), "0000")))} -> 2050-4522 | B6: María del Carmen Ibarra | C6: {=INT(RANDARRAY(40, 84) * (100 - 60) + 60)} -> 78 | D6: 69 | E6: 77 | F6: 61 | G6: 63 | H6: 94 | I6: 86 | J6: 67 | K6: 88 | L6: 83 | M6: 80 | N6: 99 | O6: 89 | P6: 70 | Q6: 60 | R6: 81 | S6: 97 | T6: 63 | U6: 99 | V6: 97 | W6: 69 | X6: 74 | Y6: 77 | Z6: 83 | AA6: 61 | AB6: 97 | AC6: 99 | AD6: 92 | AE6: 79 | AF6: 85 | AG6: 95 | AH6: 95 | AI6: 60 | AJ6: 79 | AK6: 70 | AL6: 80 | AM6: 99 | AN6: 65 | AO6: 92 | AP6: 87 | AQ6: 79 | AR6: 71 | AS6: 99 | AT6: 99 | AU6: 80 | AV6: 78 | AW6: 65 | AX6: 62 | AY6: 85 | AZ6: 80 | BA6: 64 | BB6: 65 | BC6: 74 | BD6: 99 | BE6: 86 | BF6: 62 | BG6: 67 | BH6: 80 | BI6: 83 | BJ6: 95 | BK6: 63 | BL6: 64 | BM6: 94 | BN6: 90 | BO6: 87 | BP6: 96 | BQ6: 83 | BR6: 63 | BS6: 84 | BT6: 76 | BU6: 87 | BV6: 90 | BW6: 87 | BX6: 92 | BY6: 68 | BZ6: 84 | CA6: 82 | CB6: 86 | CC6: 87 | CD6: 63 | CE6: 73 | CF6: 85 | CG6: 94 | CH6: 79
A7: 2050-2396 | B7: Federico Solís | C7: 95 | D7: 77 | E7: 61 | F7: 88 | G7: 98 | H7: 97 | I7: 86 | J7: 86 | K7: 96 | L7: 83 | M7: 98 | N7: 71 | O7: 87 | P7: 68 | Q7: 96 | R7: 80 | S7: 63 | T7: 92 | U7: 73 | V7: 77 | W7: 75 | X7: 74 | Y7: 91 | Z7: 83 | AA7: 73 | AB7: 67 | AC7: 64 | AD7: 62 | AE7: 71 | AF7: 80 | AG7: 60 | AH7: 98 | AI7: 63 | AJ7: 71 | AK7: 75 | AL7: 77 | AM7: 75 | AN7: 69 | AO7: 91 | AP7: 65 | AQ7: 86 | AR7: 72 | AS7: 79 | AT7: 93 | AU7: 98 | AV7: 77 | AW7: 66 | AX7: 82 | AY7: 97 | AZ7: 74 | BA7: 67 | BB7: 65 | BC7: 65 | BD7: 74 | BE7: 71 | BF7: 66 | BG7: 61 | BH7: 89 | BI7: 62 | BJ7: 86 | BK7: 79 | BL7: 91 | BM7: 84 | BN7: 70 | BO7: 75 | BP7: 97 | BQ7: 87 | BR7: 69 | BS7: 91 | BT7: 92 | BU7: 91 | BV7: 63 | BW7: 63 | BX7: 90 | BY7: 98 | BZ7: 62 | CA7: 81 | CB7: 69 | CC7: 95 | CD7: 75 | CE7: 85 | CF7: 83 | CG7: 95 | CH7: 93
A8: 2050-9118 | B8: José Manuel Campos | C8: 92 | D8: 83 | E8: 63 | F8: 68 | G8: 82 | H8: 89 | I8: 85 | J8: 84 | K8: 86 | L8: 80 | M8: 64 | N8: 91 | O8: 72 | P8: 88 | Q8: 85 | R8: 98 | S8: 62 | T8: 62 | U8: 60 | V8: 84 | W8: 80 | X8: 81 | Y8: 60 | Z8: 76 | AA8: 68 | AB8: 77 | AC8: 95 | AD8: 96 | AE8: 78 | AF8: 72 | AG8: 88 | AH8: 83 | AI8: 81 | AJ8: 74 | AK8: 64 | AL8: 86 | AM8: 84 | AN8: 63 | AO8: 62 | AP8: 65 | AQ8: 84 | AR8: 75 | AS8: 77 | AT8: 90 | AU8: 63 | AV8: 80 | AW8: 85 | AX8: 78 | AY8: 71 | AZ8: 77 | BA8: 90 | BB8: 71 | BC8: 81 | BD8: 91 | BE8: 82 | BF8: 65 | BG8: 76 | BH8: 84 | BI8: 65 | BJ8: 90 | BK8: 78 | BL8: 94 | BM8: 96 | BN8: 64 | BO8: 92 | BP8: 67 | BQ8: 62 | BR8: 98 | BS8: 60 | BT8: 61 | BU8: 73 | BV8: 68 | BW8: 87 | BX8: 95 | BY8: 81 | BZ8: 86 | CA8: 65 | CB8: 76 | CC8: 92 | CD8: 92 | CE8: 82 | CF8: 74 | CG8: 68 | CH8: 69
A9: 2050-3425 | B9: Gabriel Cervantes | C9: 62 | D9: 87 | E9: 74 | F9: 70 | G9: 73 | H9: 63 | I9: 88 | J9: 67 | K9: 89 | L9: 74 | M9: 83 | N9: 90 | O9: 61 | P9: 74 | Q9: 91 | R9: 61 | S9: 69 | T9: 76 | U9: 80 | V9: 83 | W9: 80 | X9: 60 | Y9: 61 | Z9: 94 | AA9: 68 | AB9: 88 | AC9: 76 | AD9: 60 | AE9: 60 | AF9: 91 | AG9: 74 | AH9: 86 | AI9: 81 | AJ9: 70 | AK9: 77 | AL9: 67 | AM9: 72 | AN9: 66 | AO9: 72 | AP9: 77 | AQ9: 65 | AR9: 75 | AS9: 84 | AT9: 91 | AU9: 67 | AV9: 64 | AW9: 60 | AX9: 74 | AY9: 80 | AZ9: 98 | BA9: 90 | BB9: 84 | BC9: 63 | BD9: 97 | BE9: 71 | BF9: 83 | BG9: 74 | BH9: 69 | BI9: 81 | BJ9: 86 | BK9: 66 | BL9: 93 | BM9: 72 | BN9: 85 | BO9: 72 | BP9: 77 | BQ9: 72 | BR9: 61 | BS9: 79 | BT9: 82 | BU9: 88 | BV9: 69 | BW9: 92 | BX9: 91 | BY9: 95 | BZ9: 89 | CA9: 90 | CB9: 95 | CC9: 64 | CD9: 70 | CE9: 85 | CF9: 64 | CG9: 63 | CH9: 82
A10: 2050-6286 | B10: Mayra Muñoz | C10: 97 | D10: 74 | E10: 80 | F10: 61 | G10: 78 | H10: 87 | I10: 91 | J10: 64 | K10: 82 | L10: 83 | M10: 91 | N10: 97 | O10: 81 | P10: 75 | Q10: 99 | R10: 92 | S10: 88 | T10: 64 | U10: 86 | V10: 83 | W10: 79 | X10: 93 | Y10: 96 | Z10: 64 | AA10: 99 | AB10: 89 | AC10: 74 | AD10: 83 | AE10: 80 | AF10: 96 | AG10: 66 | AH10: 63 | AI10: 88 | AJ10: 82 | AK10: 69 | AL10: 90 | AM10: 93 | AN10: 79 | AO10: 85 | AP10: 90 | AQ10: 79 | AR10: 72 | AS10: 99 | AT10: 76 | AU10: 62 | AV10: 60 | AW10: 78 | AX10: 74 | AY10: 84 | AZ10: 91 | BA10: 99 | BB10: 92 | BC10: 85 | BD10: 85 | BE10: 74 | BF10: 72 | BG10: 69 | BH10: 69 | BI10: 73 | BJ10: 80 | BK10: 88 | BL10: 62 | BM10: 69 | BN10: 62 | BO10: 96 | BP10: 65 | BQ10: 65 | BR10: 77 | BS10: 68 | BT10: 89 | BU10: 84 | BV10: 85 | BW10: 63 | BX10: 93 | BY10: 79 | BZ10: 72 | CA10: 84 | CB10: 90 | CC10: 75 | CD10: 91 | CE10: 63 | CF10: 92 | CG10: 95 | CH10: 93
A11: 2050-7002 | B11: Irene Mejía | C11: 60 | D11: 84 | E11: 71 | F11: 97 | G11: 93 | H11: 75 | I11: 79 | J11: 84 | K11: 73 | L11: 80 | M11: 84 | N11: 80 | O11: 96 | P11: 93 | Q11: 96 | R11: 86 | S11: 95 | T11: 78 | U11: 99 | V11: 67 | W11: 91 | X11: 69 | Y11: 84 | Z11: 66 | AA11: 76 | AB11: 89 | AC11: 60 | AD11: 62 | AE11: 93 | AF11: 65 | AG11: 84 | AH11: 90 | AI11: 79 | AJ11: 78 | AK11: 69 | AL11: 62 | AM11: 94 | AN11: 60 | AO11: 67 | AP11: 70 | AQ11: 63 | AR11: 63 | AS11: 61 | AT11: 95 | AU11: 70 | AV11: 83 | AW11: 79 | AX11: 65 | AY11: 63 | AZ11: 64 | BA11: 88 | BB11: 74 | BC11: 88 | BD11: 85 | BE11: 60 | BF11: 85 | BG11: 90 | BH11: 96 | BI11: 75 | BJ11: 60 | BK11: 71 | BL11: 69 | BM11: 66 | BN11: 81 | BO11: 66 | BP11: 72 | BQ11: 89 | BR11: 62 | BS11: 78 | BT11: 66 | BU11: 87 | BV11: 70 | BW11: 86 | BX11: 73 | BY11: 87 | BZ11: 82 | CA11: 63 | CB11: 92 | CC11: 81 | CD11: 66 | CE11: 88 | CF11: 70 | CG11: 77 | CH11: 97
A12: 2050-0323 | B12: Jesús León | C12: 83 | D12: 78 | E12: 70 | F12: 90 | G12: 66 | H12: 89 | I12: 91 | J12: 71 | K12: 90 | L12: 99 | M12: 81 | N12: 66 | O12: 78 | P12: 98 | Q12: 67 | R12: 80 | S12: 69 | T12: 95 | U12: 89 | V12: 82 | W12: 74 | X12: 92 | Y12: 63 | Z12: 85 | AA12: 99 | AB12: 64 | AC12: 65 | AD12: 67 | AE12: 70 | AF12: 84 | AG12: 97 | AH12: 61 | AI12: 92 | AJ12: 88 | AK12: 62 | AL12: 81 | AM12: 75 | AN12: 98 | AO12: 74 | AP12: 94 | AQ12: 94 | AR12: 94 | AS12: 96 | AT12: 92 | AU12: 95 | AV12: 83 | AW12: 86 | AX12: 74 | AY12: 98 | AZ12: 76 | BA12: 61 | BB12: 80 | BC12: 96 | BD12: 76 | BE12: 80 | BF12: 93 | BG12: 96 | BH12: 60 | BI12: 91 | BJ12: 92 | BK12: 95 | BL12: 70 | BM12: 87 | BN12: 61 | BO12: 92 | BP12: 91 | BQ12: 78 | BR12: 77 | BS12: 66 | BT12: 84 | BU12: 63 | BV12: 85 | BW12: 61 | BX12: 77 | BY12: 76 | BZ12: 79 | CA12: 87 | CB12: 82 | CC12: 71 | CD12: 75 | CE12: 83 | CF12: 66 | CG12: 72 | CH12: 64
A13: 2050-5644 | B13: Noé Campos | C13: 83 | D13: 66 | E13: 79 | F13: 97 | G13: 83 | H13: 63 | I13: 86 | J13: 95 | K13: 97 | L13: 67 | M13: 94 | N13: 82 | O13: 81 | P13: 66 | Q13: 72 | R13: 84 | S13: 88 | T13: 74 | U13: 61 | V13: 71 | W13: 82 | X13: 64 | Y13: 92 | Z13: 91 | AA13: 97 | AB13: 85 | AC13: 87 | AD13: 94 | AE13: 72 | AF13: 80 | AG13: 72 | AH13: 84 | AI13: 84 | AJ13: 61 | AK13: 86 | AL13: 62 | AM13: 94 | AN13: 69 | AO13: 95 | AP13: 96 | AQ13: 82 | AR13: 98 | AS13: 70 | AT13: 92 | AU13: 75 | AV13: 88 | AW13: 66 | AX13: 97 | AY13: 93 | AZ13: 61 | BA13: 85 | BB13: 75 | BC13: 84 | BD13: 99 | BE13: 85 | BF13: 92 | BG13: 95 | BH13: 67 | BI13: 92 | BJ13: 83 | BK13: 67 | BL13: 77 | BM13: 74 | BN13: 75 | BO13: 87 | BP13: 65 | BQ13: 89 | BR13: 84 | BS13: 82 | BT13: 74 | BU13: 81 | BV13: 91 | BW13: 86 | BX13: 87 | BY13: 93 | BZ13: 67 | CA13: 67 | CB13: 60 | CC13: 69 | CD13: 84 | CE13: 65 | CF13: 77 | CG13: 80 | CH13: 94
A14: 2050-3894 | B14: Daniel Ortiz | C14: 87 | D14: 66 | E14: 84 | F14: 86 | G14: 75 | H14: 98 | I14: 90 | J14: 98 | K14: 88 | L14: 81 | M14: 96 | N14: 64 | O14: 96 | P14: 70 | Q14: 98 | R14: 66 | S14: 82 | T14: 63 | U14: 73 | V14: 86 | W14: 62 | X14: 76 | Y14: 71 | Z14: 99 | AA14: 84 | AB14: 61 | AC14: 88 | AD14: 89 | AE14: 77 | AF14: 78 | AG14: 75 | AH14: 82 | AI14: 69 | AJ14: 65 | AK14: 65 | AL14: 93 | AM14: 91 | AN14: 92 | AO14: 69 | AP14: 81 | AQ14: 91 | AR14: 74 | AS14: 78 | AT14: 97 | AU14: 93 | AV14: 75 | AW14: 82 | AX14: 92 | AY14: 93 | AZ14: 97 | BA14: 62 | BB14: 61 | BC14: 94 | BD14: 77 | BE14: 95 | BF14: 84 | BG14: 85 | BH14: 99 | BI14: 67 | BJ14: 78 | BK14: 85 | BL14: 68 | BM14: 66 | BN14: 65 | BO14: 81 | BP14: 81 | BQ14: 66 | BR14: 61 | BS14: 96 | BT14: 98 | BU14: 94 | BV14: 83 | BW14: 60 | BX14: 93 | BY14: 89 | BZ14: 68 | CA14: 94 | CB14: 89 | CC14: 82 | CD14: 82 | CE14: 69 | CF14: 87 | CG14: 95 | CH14: 72
A15: 2050-0590 | B15: Santiago López | C15: 68 | D15: 66 | E15: 83 | F15: 91 | G15: 79 | H15: 81 | I15: 85 | J15: 64 | K15: 82 | L15: 90 | M15: 81 | N15: 67 | O15: 93 | P15: 62 | Q15: 72 | R15: 68 | S15: 75 | T15: 68 | U15: 63 | V15: 68 | W15: 99 | X15: 66 | Y15: 63 | Z15: 72 | AA15: 93 | AB15: 96 | AC15: 95 | AD15: 67 | AE15: 61 | AF15: 91 | AG15: 68 | AH15: 74 | AI15: 65 | AJ15: 98 | AK15: 80 | AL15: 68 | AM15: 85 | AN15: 65 | AO15: 68 | AP15: 84 | AQ15: 71 | AR15: 93 | AS15: 81 | AT15: 85 | AU15: 90 | AV15: 88 | AW15: 67 | AX15: 93 | AY15: 69 | AZ15: 85 | BA15: 61 | BB15: 74 | BC15: 65 | BD15: 88 | BE15: 65 | BF15: 90 | BG15: 96 | BH15: 69 | BI15: 85 | BJ15: 66 | BK15: 63 | BL15: 74 | BM15: 80 | BN15: 76 | BO15: 90 | BP15: 84 | BQ15: 77 | BR15: 69 | BS15: 67 | BT15: 86 | BU15: 86 | BV15: 73 | BW15: 81 | BX15: 96 | BY15: 78 | BZ15: 74 | CA15: 96 | CB15: 70 | CC15: 99 | CD15: 80 | CE15: 81 | CF15: 80 | CG15: 95 | CH15: 74
A16: 2050-7665 | B16: Catalina Espinoza | C16: 83 | D16: 74 | E16: 86 | F16: 79 | G16: 84 | H16: 86 | I16: 88 | J16: 99 | K16: 61 | L16: 68 | M16: 85 | N16: 72 | O16: 88 | P16: 82 | Q16: 89 | R16: 63 | S16: 75 | T16: 75 | U16: 94 | V16: 60 | W16: 80 | X16: 78 | Y16: 66 | Z16: 62 | AA16: 93 | AB16: 96 | AC16: 71 | AD16: 85 | AE16: 83 | AF16: 69 | AG16: 70 | AH16: 86 | AI16: 78 | AJ16: 63 | AK16: 90 | AL16: 81 | AM16: 70 | AN16: 74 | AO16: 80 | AP16: 85 | AQ16: 89 | AR16: 69 | AS16: 67 | AT16: 94 | AU16: 90 | AV16: 95 | AW16: 79 | AX16: 64 | AY16: 79 | AZ16: 62 | BA16: 82 | BB16: 96 | BC16: 91 | BD16: 83 | BE16: 77 | BF16: 77 | BG16: 60 | BH16: 71 | BI16: 69 | BJ16: 82 | BK16: 67 | BL16: 97 | BM16: 61 | BN16: 84 | BO16: 66 | BP16: 80 | BQ16: 72 | BR16: 92 | BS16: 80 | BT16: 70 | BU16: 62 | BV16: 72 | BW16: 69 | BX16: 93 | BY16: 76 | BZ16: 78 | CA16: 92 | CB16: 63 | CC16: 95 | CD16: 74 | CE16: 92 | CF16: 73 | CG16: 73 | CH16: 76
A17: 2050-8616 | B17: Cristina Medina | C17: 83 | D17: 89 | E17: 85 | F17: 79 | G17: 75 | H17: 84 | I17: 92 | J17: 91 | K17: 64 | L17: 95 | M17: 72 | N17: 95 | O17: 70 | P17: 67 | Q17: 81 | R17: 70 | S17: 72 | T17: 67 | U17: 75 | V17: 80 | W17: 82 | X17: 97 | Y17: 96 | Z17: 63 | AA17: 60 | AB17: 77 | AC17: 90 | AD17: 73 | AE17: 63 | AF17: 75 | AG17: 61 | AH17: 83 | AI17: 70 | AJ17: 93 | AK17: 89 | AL17: 67 | AM17: 99 | AN17: 70 | AO17: 75 | AP17: 81 | AQ17: 97 | AR17: 78 | AS17: 87 | AT17: 88 | AU17: 71 | AV17: 87 | AW17: 97 | AX17: 69 | AY17: 93 | AZ17: 87 | BA17: 95 | BB17: 67 | BC17: 64 | BD17: 99 | BE17: 64 | BF17: 77 | BG17: 66 | BH17: 77 | BI17: 82 | BJ17: 67 | BK17: 61 | BL17: 93 | BM17: 66 | BN17: 74 | BO17: 61 | BP17: 82 | BQ17: 75 | BR17: 77 | BS17: 89 | BT17: 72 | BU17: 88 | BV17: 80 | BW17: 65 | BX17: 69 | BY17: 89 | BZ17: 85 | CA17: 62 | CB17: 66 | CC17: 78 | CD17: 98 | CE17: 60 | CF17: 96 | CG17: 73 | CH17: 74
A18: 2050-9473 | B18: Gregorio Reyes | C18: 66 | D18: 70 | E18: 81 | F18: 71 | G18: 76 | H18: 84 | I18: 77 | J18: 96 | K18: 64 | L18: 94 | M18: 87 | N18: 84 | O18: 95 | P18: 93 | Q18: 78 | R18: 60 | S18: 84 | T18: 86 | U18: 93 | V18: 61 | W18: 72 | X18: 74 | Y18: 89 | Z18: 80 | AA18: 61 | AB18: 68 | AC18: 98 | AD18: 79 | AE18: 62 | AF18: 91 | AG18: 93 | AH18: 90 | AI18: 80 | AJ18: 80 | AK18: 84 | AL18: 67 | AM18: 69 | AN18: 75 | AO18: 82 | AP18: 60 | AQ18: 89 | AR18: 86 | AS18: 67 | AT18: 83 | AU18: 98 | AV18: 87 | AW18: 85 | AX18: 64 | AY18: 63 | AZ18: 64 | BA18: 83 | BB18: 65 | BC18: 90 | BD18: 67 | BE18: 88 | BF18: 87 | BG18: 62 | BH18: 90 | BI18: 86 | BJ18: 93 | BK18: 73 | BL18: 80 | BM18: 68 | BN18: 98 | BO18: 88 | BP18: 89 | BQ18: 87 | BR18: 76 | BS18: 78 | BT18: 77 | BU18: 94 | BV18: 69 | BW18: 78 | BX18: 60 | BY18: 96 | BZ18: 92 | CA18: 95 | CB18: 73 | CC18: 76 | CD18: 98 | CE18: 89 | CF18: 97 | CG18: 60 | CH18: 72
... A45: 2050-0929 | B45: Elizabeth Rangel | C45: 95 | D45: 68 | E45: 75 | F45: 76 | G45: 65 | H45: 61 | I45: 69 | J45: 85 | K45: 70 | L45: 76 | M45: 89 | N45: 65 | O45: 73 | P45: 76 | Q45: 64 | R45: 73 | S45: 96 | T45: 60 | U45: 77 | V45: 77 | W45: 99 | X45: 73 | Y45: 68 | Z45: 95 | AA45: 97 | AB45: 69 | AC45: 66 | AD45: 83 | AE45: 67 | AF45: 61 | AG45: 80 | AH45: 74 | AI45: 89 | AJ45: 89 | AK45: 90 | AL45: 83 | AM45: 62 | AN45: 84 | AO45: 61 | AP45: 67 | AQ45: 62 | AR45: 74 | AS45: 87 | AT45: 86 | AU45: 76 | AV45: 66 | AW45: 80 | AX45: 83 | AY45: 95 | AZ45: 81 | BA45: 66 | BB45: 79 | BC45: 99 | BD45: 79 | BE45: 97 | BF45: 73 | BG45: 63 | BH45: 88 | BI45: 86 | BJ45: 96 | BK45: 65 | BL45: 84 | BM45: 65 | BN45: 76 | BO45: 66 | BP45: 86 | BQ45: 98 | BR45: 97 | BS45: 79 | BT45: 72 | BU45: 94 | BV45: 99 | BW45: 88 | BX45: 66 | BY45: 97 | BZ45: 77 | CA45: 78 | CB45: 65 | CC45: 88 | CD45: 81 | CE45: 82 | CF45: 91 | CG45: 80 | CH45: 96
B47: CLO Average | C47: =AVERAGE(C6:C45) -> 76.075 | D47: =AVERAGE(D6:D45) -> 76.35 | E47: =AVERAGE(E6:E45) -> 79.625 | F47: =AVERAGE(F6:F45) -> 76.275 | G47: =AVERAGE(G6:G45) -> 77.625 | H47: =AVERAGE(H6:H45) -> 80.5 | I47: =AVERAGE(I6:I45) -> 81.225 | J47: =AVERAGE(J6:J45) -> 80 | ... CH47: =AVERAGE(CH6:CH45) -> 78.425
B48: Total Number of Students | C48: =COUNTA(C6:C45) -> 40 | D48: =COUNTA(D6:D45) -> 40 | E48: =COUNTA(E6:E45) -> 40 | F48: =COUNTA(F6:F45) -> 40 | G48: =COUNTA(G6:G45) -> 40 | H48: =COUNTA(H6:H45) -> 40 | I48: =COUNTA(I6:I45) -> 40 | J48: =COUNTA(J6:J45) -> 40 | ... CH48: =COUNTA(CH6:CH45) -> 40
B49: Total Number of GS Students | C49: =COUNTIF(C6:C45, ">=70") -> 22 | D49: =COUNTIF(D6:D45, ">=70") -> 28 | E49: =COUNTIF(E6:E45, ">=70") -> 35 | F49: =COUNTIF(F6:F45, ">=70") -> 28 | G49: =COUNTIF(G6:G45, ">=70") -> 27 | H49: =COUNTIF(H6:H45, ">=70") -> 32 | I49: =COUNTIF(I6:I45, ">=70") -> 31 | J49: =COUNTIF(J6:J45, ">=70") -> 27 | ... CH49: =COUNTIF(CH6:CH45, ">=70") -> 29
B50: CLO Attainment | C50: =COUNTIF(C6:C45, ">=70")/COUNTA(C6:C45) * 100 -> 55 | D50: =COUNTIF(D6:D45, ">=70")/COUNTA(D6:D45) * 100 -> 70 | E50: =COUNTIF(E6:E45, ">=70")/COUNTA(E6:E45) * 100 -> 87.5 | F50: =COUNTIF(F6:F45, ">=70")/COUNTA(F6:F45) * 100 -> 70 | G50: =COUNTIF(G6:G45, ">=70")/COUNTA(G6:G45) * 100 -> 67.5 | H50: =COUNTIF(H6:H45, ">=70")/COUNTA(H6:H45) * 100 -> 80 | I50: =COUNTIF(I6:I45, ">=70")/COUNTA(I6:I45) * 100 -> 77.5 | J50: =COUNTIF(J6:J45, ">=70")/COUNTA(J6:J45) * 100 -> 67.5 | ... CH50: =COUNTIF(CH6:CH45, ">=70")/COUNTA(CH6:CH45) * 100 -> 72.5
B51: Executive Summary Alert | C51: =IF(C50>=70, "✅", "❌") -> ❌ | D51: =IF(D50>=70, "✅", "❌") -> ✅ | E51: =IF(E50>=70, "✅", "❌") -> ✅ | F51: =IF(F50>=70, "✅", "❌") -> ✅ | G51: =IF(G50>=70, "✅", "❌") -> ❌ | H51: =IF(H50>=70, "✅", "❌") -> ✅ | I51: =IF(I50>=70, "✅", "❌") -> ✅ | J51: =IF(J50>=70, "✅", "❌") -> ❌ | ... CH51: =IF(CH50>=70, "✅", "❌") -> ✅
A54: Nota Bene:
A55: 1. Performance Critera is set to:
B56: Benchmark: 70%
B57: Target: 70%
A58: 2. CQI Alert Signs:
B59: ✅ - Target Met
B60: ❌ - Action Required
A61: 3. GS - A student who achieved the benchmark or greater is considered Good Standing (GS)

Sheet Mapping
A1: Mapping of CLO to PLO
A3: Course Code | B3: CLO No. | C3: Program Learning Outcome (PLO)
C4: PLO1 | D4: PLO2 | E4: PLO3 | F4: PLO4 | G4: PLO5 | H4: PLO6 | I4: PLO7 | J4: PLO8 | K4: PLO9 | L4: PLO10 | M4: PLO11
A5: CCC100 | C5: =TEXTJOIN(", ", TRUE, C6:C8) -> I | D5: =TEXTJOIN(", ", TRUE, D6:D8) -> I | E5: =TEXTJOIN(", ", TRUE, E6:E8) -> I | F5: =TEXTJOIN(", ", TRUE, F6:F8) | G5: =TEXTJOIN(", ", TRUE, G6:G8) | H5: =TEXTJOIN(", ", TRUE, H6:H8) | I5: =TEXTJOIN(", ", TRUE, I6:I8) | J5: =TEXTJOIN(", ", TRUE, J6:J8) | ... M5: =TEXTJOIN(", ", TRUE, M6:M8)
B6: CLO1 | C6: I
B7: CLO2 | D7: I
B8: CLO3 | E8: I
A9: CCC101 | C9: =TEXTJOIN(", ", TRUE, C10:C12) -> I | D9: =TEXTJOIN(", ", TRUE, D10:D12) -> I | E9: =TEXTJOIN(", ", TRUE, E10:E12) -> I | F9: =TEXTJOIN(", ", TRUE, F10:F12) | G9: =TEXTJOIN(", ", TRUE, G10:G12) | H9: =TEXTJOIN(", ", TRUE, H10:H12) | I9: =TEXTJOIN(", ", TRUE, I10:I12) | J9: =TEXTJOIN(", ", TRUE, J10:J12) | ... M9: =TEXTJOIN(", ", TRUE, M10:M12)
B10: CLO1 | C10: I
B11: CLO2 | D11: I
B12: CLO3 | E12: I
A13: CCC102 | C13: =TEXTJOIN(", ", TRUE, C14:C16) -> I | D13: =TEXTJOIN(", ", TRUE, D14:D16) -> I | E13: =TEXTJOIN(", ", TRUE, E14:E16) -> I | F13: =TEXTJOIN(", ", TRUE, F14:F16) | G13: =TEXTJOIN(", ", TRUE, G14:G16) | H13: =TEXTJOIN(", ", TRUE, H14:H16) | I13: =TEXTJOIN(", ", TRUE, I14:I16) | J13: =TEXTJOIN(", ", TRUE, J14:J16) | ... M13: =TEXTJOIN(", ", TRUE, M14:M16)
B14: CLO1 | C14: I
B15: CLO2 | D15: I
B16: CLO3 | E16: I
A17: CCC121 | C17: =TEXTJOIN(", ", TRUE, C18:C20) -> P | D17: =TEXTJOIN(", ", TRUE, D18:D20) -> P | E17: =TEXTJOIN(", ", TRUE, E18:E20) -> P | F17: =TEXTJOIN(", ", TRUE, F18:F20) | G17: =TEXTJOIN(", ", TRUE, G18:G20) | H17: =TEXTJOIN(", ", TRUE, H18:H20) | I17: =TEXTJOIN(", ", TRUE, I18:I20) | J17: =TEXTJOIN(", ", TRUE, J18:J20) | ... M17: =TEXTJOIN(", ", TRUE, M18:M20)
B18: CLO1 | C18: P
B19: CLO2 | D19: P
B20: CLO3 | E20: P
A21: CCC151 | C21: =TEXTJOIN(", ", TRUE, C22:C24) -> P | D21: =TEXTJOIN(", ", TRUE, D22:D24) -> P | E21: =TEXTJOIN(", ", TRUE, E22:E24) -> P | F21: =TEXTJOIN(", ", TRUE, F22:F24) | G21: =TEXTJOIN(", ", TRUE, G22:G24) | H21: =TEXTJOIN(", ", TRUE, H22:H24) | I21: =TEXTJOIN(", ", TRUE, I22:I24) | J21: =TEXTJOIN(", ", TRUE, J22:J24) | ... M21: =TEXTJOIN(", ", TRUE, M22:M24)
B22: CLO1 | C22: P
B23: CLO2 | D23: P
B24: CLO3 | E24: P
A25: CCC181 | C25: =TEXTJOIN(", ", TRUE, C26:C28) -> D | D25: =TEXTJOIN(", ", TRUE, D26:D28) -> D | E25: =TEXTJOIN(", ", TRUE, E26:E28) -> D | F25: =TEXTJOIN(", ", TRUE, F26:F28) | G25: =TEXTJOIN(", ", TRUE, G26:G28) | H25: =TEXTJOIN(", ", TRUE, H26:H28) | I25: =TEXTJOIN(", ", TRUE, I26:I28) | J25: =TEXTJOIN(", ", TRUE, J26:J28) | ... M25: =TEXTJOIN(", ", TRUE, M26:M28)
B26: CLO1 | C26: D
B27: CLO2 | D27: D
B28: CLO3 | E28: D
A29: CSC109 | C29: =TEXTJOIN(", ", TRUE, C30:C32) | D29: =TEXTJOIN(", ", TRUE, D30:D32) | E29: =TEXTJOIN(", ", TRUE, E30:E32) | F29: =TEXTJOIN(", ", TRUE, F30:F32) | G29: =TEXTJOIN(", ", TRUE, G30:G32) | H29: =TEXTJOIN(", ", TRUE, H30:H32) | I29: =TEXTJOIN(", ", TRUE, I30:I32) | J29: =TEXTJOIN(", ", TRUE, J30:J32) -> D | ... M29: =TEXTJOIN(", ", TRUE, M30:M32) -> D, D, D
B30: CLO1 | J30: D | M30: D
B31: CLO2 | K31: D | M31: D
B32: CLO3 | L32: D | M32: D
A33: CSC112 | C33: =TEXTJOIN(", ", TRUE, C34:C36) | D33: =TEXTJOIN(", ", TRUE, D34:D36) | E33: =TEXTJOIN(", ", TRUE, E34:E36) | F33: =TEXTJOIN(", ", TRUE, F34:F36) -> I | G33: =TEXTJOIN(", ", TRUE, G34:G36) -> P | H33: =TEXTJOIN(", ", TRUE, H34:H36) -> P | I33: =TEXTJOIN(", ", TRUE, I34:I36) | J33: =TEXTJOIN(", ", TRUE, J34:J36) | ... M33: =TEXTJOIN(", ", TRUE, M34:M36)
B34: CLO1 | F34: I
B35: CLO2 | G35: P
B36: CLO3 | H36: P
A37: CSC113 | C37: =TEXTJOIN(", ", TRUE, C38:C40) | D37: =TEXTJOIN(", ", TRUE, D38:D40) | E37: =TEXTJOIN(", ", TRUE, E38:E40) | F37: =TEXTJOIN(", ", TRUE, F38:F40) -> I | G37: =TEXTJOIN(", ", TRUE, G38:G40) -> P | H37: =TEXTJOIN(", ", TRUE, H38:H40) -> P | I37: =TEXTJOIN(", ", TRUE, I38:I40) | J37: =TEXTJOIN(", ", TRUE, J38:J40) | ... M37: =TEXTJOIN(", ", TRUE, M38:M40) -> I
B38: CLO1 | F38: I | L38: I
B39: CLO2 | G39: P | M39: I
B40: CLO3 | H40: P
A41: CSC124 | C41: =TEXTJOIN(", ", TRUE, C42:C44) -> I | D41: =TEXTJOIN(", ", TRUE, D42:D44) -> I | E41: =TEXTJOIN(", ", TRUE, E42:E44) -> P | F41: =TEXTJOIN(", ", TRUE, F42:F44) -> I | G41: =TEXTJOIN(", ", TRUE, G42:G44) -> I | H41: =TEXTJOIN(", ", TRUE, H42:H44) -> P | I41: =TEXTJOIN(", ", TRUE, I42:I44) | J41: =TEXTJOIN(", ", TRUE, J42:J44) | ... M41: =TEXTJOIN(", ", TRUE, M42:M44)
...

Sheet MapWeight
A1: Conversion to Mapping Values ("I" = 1, "P" = 2, "D" = 3)
A3: Course Code | B3: CLO No. | C3: Program Learning Outcome (PLO)
C4: PLO1 | D4: PLO2 | E4: PLO3 | F4: PLO4 | G4: PLO5 | H4: PLO6 | I4: PLO7 | J4: PLO8 | K4: PLO9 | L4: PLO10 | M4: PLO11
A6: All Courses | C6: =C7+C11+C15+C19+C23+C27+C31+C35+C39+C43+C47+C51+C55+C59+C63+C67+C71+C75+C79+C83+C87+C91+C95+C99+C103+C107+C111+C115 -> 48 | D6: =D7+D11+D15+D19+D23+D27+D31+D35+D39+D43+D47+D51+D55+D59+D63+D67+D71+D75+D79+D83+D87+D91+D95+D99+D103+D107+D111+D115 -> 52 | E6: =E7+E11+E15+E19+E23+E27+E31+E35+E39+E43+E47+E51+E55+E59+E63+E67+E71+E75+E79+E83+E87+E91+E95+E99+E103+E107+E111+E115 -> 70 | F6: =F7+F11+F15+F19+F23+F27+F31+F35+F39+F43+F47+F51+F55+F59+F63+F67+F71+F75+F79+F83+F87+F91+F95+F99+F103+F107+F111+F115 -> 47 | G6: =G7+G11+G15+G19+G23+G27+G31+G35+G39+G43+G47+G51+G55+G59+G63+G67+G71+G75+G79+G83+G87+G91+G95+G99+G103+G107+G111+G115 -> 52 | H6: =H7+H11+H15+H19+H23+H27+H31+H35+H39+H43+H47+H51+H55+H59+H63+H67+H71+H75+H79+H83+H87+H91+H95+H99+H103+H107+H111+H115 -> 60 | I6: =I7+I11+I15+I19+I23+I27+I31+I35+I39+I43+I47+I51+I55+I59+I63+I67+I71+I75+I79+I83+I87+I91+I95+I99+I103+I107+I111+I115 -> 40 | J6: =J7+J11+J15+J19+J23+J27+J31+J35+J39+J43+J47+J51+J55+J59+J63+J67+J71+J75+J79+J83+J87+J91+J95+J99+J103+J107+J111+J115 -> 36 | ... M6: =M7+M11+M15+M19+M23+M27+M31+M35+M39+M43+M47+M51+M55+M59+M63+M67+M71+M75+M79+M83+M87+M91+M95+M99+M103+M107+M111+M115 -> 37
A7: CCC100 | C7: =SUM(C8:C10) -> 1 | D7: =SUM(D8:D10) -> 1 | E7: =SUM(E8:E10) -> 1 | F7: =SUM(F8:F10) -> 0 | G7: =SUM(G8:G10) -> 0 | H7: =SUM(H8:H10) -> 0 | I7: =SUM(I8:I10) -> 0 | J7: =SUM(J8:J10) -> 0 | ... M7: =SUM(M8:M10) -> 0
B8: CLO1 | C8: =IFS(Mapping!C6="I", 1, Mapping!C6="P", 2, Mapping!C6="D", 3, TRUE, "") -> 1 | D8: =IFS(Mapping!D6="I", 1, Mapping!D6="P", 2, Mapping!D6="D", 3, TRUE, "") | E8: =IFS(Mapping!E6="I", 1, Mapping!E6="P", 2, Mapping!E6="D", 3, TRUE, "") | F8: =IFS(Mapping!F6="I", 1, Mapping!F6="P", 2, Mapping!F6="D", 3, TRUE, "") | G8: =IFS(Mapping!G6="I", 1, Mapping!G6="P", 2, Mapping!G6="D", 3, TRUE, "") | H8: =IFS(Mapping!H6="I", 1, Mapping!H6="P", 2, Mapping!H6="D", 3, TRUE, "") | I8: =IFS(Mapping!I6="I", 1, Mapping!I6="P", 2, Mapping!I6="D", 3, TRUE, "") | J8: =IFS(Mapping!J6="I", 1, Mapping!J6="P", 2, Mapping!J6="D", 3, TRUE, "") | ... M8: =IFS(Mapping!M6="I", 1, Mapping!M6="P", 2, Mapping!M6="D", 3, TRUE, "")
B9: CLO2 | C9: =IFS(Mapping!C7="I", 1, Mapping!C7="P", 2, Mapping!C7="D", 3, TRUE, "") | D9: =IFS(Mapping!D7="I", 1, Mapping!D7="P", 2, Mapping!D7="D", 3, TRUE, "") -> 1 | E9: =IFS(Mapping!E7="I", 1, Mapping!E7="P", 2, Mapping!E7="D", 3, TRUE, "") | F9: =IFS(Mapping!F7="I", 1, Mapping!F7="P", 2, Mapping!F7="D", 3, TRUE, "") | G9: =IFS(Mapping!G7="I", 1, Mapping!G7="P", 2, Mapping!G7="D", 3, TRUE, "") | H9: =IFS(Mapping!H7="I", 1, Mapping!H7="P", 2, Mapping!H7="D", 3, TRUE, "") | I9: =IFS(Mapping!I7="I", 1, Mapping!I7="P", 2, Mapping!I7="D", 3, TRUE, "") | J9: =IFS(Mapping!J7="I", 1, Mapping!J7="P", 2, Mapping!J7="D", 3, TRUE, "") | ... M9: =IFS(Mapping!M7="I", 1, Mapping!M7="P", 2, Mapping!M7="D", 3, TRUE, "")
B10: CLO3 | C10: =IFS(Mapping!C8="I", 1, Mapping!C8="P", 2, Mapping!C8="D", 3, TRUE, "") | D10: =IFS(Mapping!D8="I", 1, Mapping!D8="P", 2, Mapping!D8="D", 3, TRUE, "") | E10: =IFS(Mapping!E8="I", 1, Mapping!E8="P", 2, Mapping!E8="D", 3, TRUE, "") -> 1 | F10: =IFS(Mapping!F8="I", 1, Mapping!F8="P", 2, Mapping!F8="D", 3, TRUE, "") | G10: =IFS(Mapping!G8="I", 1, Mapping!G8="P", 2, Mapping!G8="D", 3, TRUE, "") | H10: =IFS(Mapping!H8="I", 1, Mapping!H8="P", 2, Mapping!H8="D", 3, TRUE, "") | I10: =IFS(Mapping!I8="I", 1, Mapping!I8="P", 2, Mapping!I8="D", 3, TRUE, "") | J10: =IFS(Mapping!J8="I", 1, Mapping!J8="P", 2, Mapping!J8="D", 3, TRUE, "") | ... M10: =IFS(Mapping!M8="I", 1, Mapping!M8="P", 2, Mapping!M8="D", 3, TRUE, "")
A11: CCC101 | C11: =SUM(C12:C14) -> 1 | D11: =SUM(D12:D14) -> 1 | E11: =SUM(E12:E14) -> 1 | F11: =SUM(F12:F14) -> 0 | G11: =SUM(G12:G14) -> 0 | H11: =SUM(H12:H14) -> 0 | I11: =SUM(I12:I14) -> 0 | J11: =SUM(J12:J14) -> 0 | ... M11: =SUM(M12:M14) -> 0
B12: CLO1 | C12: =IFS(Mapping!C10="I", 1, Mapping!C10="P", 2, Mapping!C10="D", 3, TRUE, "") -> 1 | D12: =IFS(Mapping!D10="I", 1, Mapping!D10="P", 2, Mapping!D10="D", 3, TRUE, "") | E12: =IFS(Mapping!E10="I", 1, Mapping!E10="P", 2, Mapping!E10="D", 3, TRUE, "") | F12: =IFS(Mapping!F10="I", 1, Mapping!F10="P", 2, Mapping!F10="D", 3, TRUE, "") | G12: =IFS(Mapping!G10="I", 1, Mapping!G10="P", 2, Mapping!G10="D", 3, TRUE, "") | H12: =IFS(Mapping!H10="I", 1, Mapping!H10="P", 2, Mapping!H10="D", 3, TRUE, "") | I12: =IFS(Mapping!I10="I", 1, Mapping!I10="P", 2, Mapping!I10="D", 3, TRUE, "") | J12: =IFS(Mapping!J10="I", 1, Mapping!J10="P", 2, Mapping!J10="D", 3, TRUE, "") | ... M12: =IFS(Mapping!M10="I", 1, Mapping!M10="P", 2, Mapping!M10="D", 3, TRUE, "")
B13: CLO2 | C13: =IFS(Mapping!C11="I", 1, Mapping!C11="P", 2, Mapping!C11="D", 3, TRUE, "") | D13: =IFS(Mapping!D11="I", 1, Mapping!D11="P", 2, Mapping!D11="D", 3, TRUE, "") -> 1 | E13: =IFS(Mapping!E11="I", 1, Mapping!E11="P", 2, Mapping!E11="D", 3, TRUE, "") | F13: =IFS(Mapping!F11="I", 1, Mapping!F11="P", 2, Mapping!F11="D", 3, TRUE, "") | G13: =IFS(Mapping!G11="I", 1, Mapping!G11="P", 2, Mapping!G11="D", 3, TRUE, "") | H13: =IFS(Mapping!H11="I", 1, Mapping!H11="P", 2, Mapping!H11="D", 3, TRUE, "") | I13: =IFS(Mapping!I11="I", 1, Mapping!I11="P", 2, Mapping!I11="D", 3, TRUE, "") | J13: =IFS(Mapping!J11="I", 1, Mapping!J11="P", 2, Mapping!J11="D", 3, TRUE, "") | ... M13: =IFS(Mapping!M11="I", 1, Mapping!M11="P", 2, Mapping!M11="D", 3, TRUE, "")
B14: CLO3 | C14: =IFS(Mapping!C12="I", 1, Mapping!C12="P", 2, Mapping!C12="D", 3, TRUE, "") | D14: =IFS(Mapping!D12="I", 1, Mapping!D12="P", 2, Mapping!D12="D", 3, TRUE, "") | E14: =IFS(Mapping!E12="I", 1, Mapping!E12="P", 2, Mapping!E12="D", 3, TRUE, "") -> 1 | F14: =IFS(Mapping!F12="I", 1, Mapping!F12="P", 2, Mapping!F12="D", 3, TRUE, "") | G14: =IFS(Mapping!G12="I", 1, Mapping!G12="P", 2, Mapping!G12="D", 3, TRUE, "") | H14: =IFS(Mapping!H12="I", 1, Mapping!H12="P", 2, Mapping!H12="D", 3, TRUE, "") | I14: =IFS(Mapping!I12="I", 1, Mapping!I12="P", 2, Mapping!I12="D", 3, TRUE, "") | J14: =IFS(Mapping!J12="I", 1, Mapping!J12="P", 2, Mapping!J12="D", 3, TRUE, "") | ... M14: =IFS(Mapping!M12="I", 1, Mapping!M12="P", 2, Mapping!M12="D", 3, TRUE, "")
A15: CCC102 | C15: =SUM(C16:C18) -> 1 | D15: =SUM(D16:D18) -> 1 | E15: =SUM(E16:E18) -> 1 | F15: =SUM(F16:F18) -> 0 | G15: =SUM(G16:G18) -> 0 | H15: =SUM(H16:H18) -> 0 | I15: =SUM(I16:I18) -> 0 | J15: =SUM(J16:J18) -> 0 | ... M15: =SUM(M16:M18) -> 0
B16: CLO1 | C16: =IFS(Mapping!C14="I", 1, Mapping!C14="P", 2, Mapping!C14="D", 3, TRUE, "") -> 1 | D16: =IFS(Mapping!D14="I", 1, Mapping!D14="P", 2, Mapping!D14="D", 3, TRUE, "") | E16: =IFS(Mapping!E14="I", 1, Mapping!E14="P", 2, Mapping!E14="D", 3, TRUE, "") | F16: =IFS(Mapping!F14="I", 1, Mapping!F14="P", 2, Mapping!F14="D", 3, TRUE, "") | G16: =IFS(Mapping!G14="I", 1, Mapping!G14="P", 2, Mapping!G14="D", 3, TRUE, "") | H16: =IFS(Mapping!H14="I", 1, Mapping!H14="P", 2, Mapping!H14="D", 3, TRUE, "") | I16: =IFS(Mapping!I14="I", 1, Mapping!I14="P", 2, Mapping!I14="D", 3, TRUE, "") | J16: =IFS(Mapping!J14="I", 1, Mapping!J14="P", 2, Mapping!J14="D", 3, TRUE, "") | ... M16: =IFS(Mapping!M14="I", 1, Mapping!M14="P", 2, Mapping!M14="D", 3, TRUE, "")
B17: CLO2 | C17: =IFS(Mapping!C15="I", 1, Mapping!C15="P", 2, Mapping!C15="D", 3, TRUE, "") | D17: =IFS(Mapping!D15="I", 1, Mapping!D15="P", 2, Mapping!D15="D", 3, TRUE, "") -> 1 | E17: =IFS(Mapping!E15="I", 1, Mapping!E15="P", 2, Mapping!E15="D", 3, TRUE, "") | F17: =IFS(Mapping!F15="I", 1, Mapping!F15="P", 2, Mapping!F15="D", 3, TRUE, "") | G17: =IFS(Mapping!G15="I", 1, Mapping!G15="P", 2, Mapping!G15="D", 3, TRUE, "") | H17: =IFS(Mapping!H15="I", 1, Mapping!H15="P", 2, Mapping!H15="D", 3, TRUE, "") | I17: =IFS(Mapping!I15="I", 1, Mapping!I15="P", 2, Mapping!I15="D", 3, TRUE, "") | J17: =IFS(Mapping!J15="I", 1, Mapping!J15="P", 2, Mapping!J15="D", 3, TRUE, "") | ... M17: =IFS(Mapping!M15="I", 1, Mapping!M15="P", 2, Mapping!M15="D", 3, TRUE, "")
B18: CLO3 | C18: =IFS(Mapping!C16="I", 1, Mapping!C16="P", 2, Mapping!C16="D", 3, TRUE, "") | D18: =IFS(Mapping!D16="I", 1, Mapping!D16="P", 2, Mapping!D16="D", 3, TRUE, "") | E18: =IFS(Mapping!E16="I", 1, Mapping!E16="P", 2, Mapping!E16="D", 3, TRUE, "") -> 1 | F18: =IFS(Mapping!F16="I", 1, Mapping!F16="P", 2, Mapping!F16="D", 3, TRUE, "") | G18: =IFS(Mapping!G16="I", 1, Mapping!G16="P", 2, Mapping!G16="D", 3, TRUE, "") | H18: =IFS(Mapping!H16="I", 1, Mapping!H16="P", 2, Mapping!H16="D", 3, TRUE, "") | I18: =IFS(Mapping!I16="I", 1, Mapping!I16="P", 2, Mapping!I16="D", 3, TRUE, "") | J18: =IFS(Mapping!J16="I", 1, Mapping!J16="P", 2, Mapping!J16="D", 3, TRUE, "") | ... M18: =IFS(Mapping!M16="I", 1, Mapping!M16="P", 2, Mapping!M16="D", 3, TRUE, "")
A19: CCC121 | C19: =SUM(C20:C22) -> 2 | D19: =SUM(D20:D22) -> 2 | E19: =SUM(E20:E22) -> 2 | F19: =SUM(F20:F22) -> 0 | G19: =SUM(G20:G22) -> 0 | H19: =SUM(H20:H22) -> 0 | I19: =SUM(I20:I22) -> 0 | J19: =SUM(J20:J22) -> 0 | ... M19: =SUM(M20:M22) -> 0
B20: CLO1 | C20: =IFS(Mapping!C18="I", 1, Mapping!C18="P", 2, Mapping!C18="D", 3, TRUE, "") -> 2 | D20: =IFS(Mapping!D18="I", 1, Mapping!D18="P", 2, Mapping!D18="D", 3, TRUE, "") | E20: =IFS(Mapping!E18="I", 1, Mapping!E18="P", 2, Mapping!E18="D", 3, TRUE, "") | F20: =IFS(Mapping!F18="I", 1, Mapping!F18="P", 2, Mapping!F18="D", 3, TRUE, "") | G20: =IFS(Mapping!G18="I", 1, Mapping!G18="P", 2, Mapping!G18="D", 3, TRUE, "") | H20: =IFS(Mapping!H18="I", 1, Mapping!H18="P", 2, Mapping!H18="D", 3, TRUE, "") | I20: =IFS(Mapping!I18="I", 1, Mapping!I18="P", 2, Mapping!I18="D", 3, TRUE, "") | J20: =IFS(Mapping!J18="I", 1, Mapping!J18="P", 2, Mapping!J18="D", 3, TRUE, "") | ... M20: =IFS(Mapping!M18="I", 1, Mapping!M18="P", 2, Mapping!M18="D", 3, TRUE, "")
B21: CLO2 | C21: =IFS(Mapping!C19="I", 1, Mapping!C19="P", 2, Mapping!C19="D", 3, TRUE, "") | D21: =IFS(Mapping!D19="I", 1, Mapping!D19="P", 2, Mapping!D19="D", 3, TRUE, "") -> 2 | E21: =IFS(Mapping!E19="I", 1, Mapping!E19="P", 2, Mapping!E19="D", 3, TRUE, "") | F21: =IFS(Mapping!F19="I", 1, Mapping!F19="P", 2, Mapping!F19="D", 3, TRUE, "") | G21: =IFS(Mapping!G19="I", 1, Mapping!G19="P", 2, Mapping!G19="D", 3, TRUE, "") | H21: =IFS(Mapping!H19="I", 1, Mapping!H19="P", 2, Mapping!H19="D", 3, TRUE, "") | I21: =IFS(Mapping!I19="I", 1, Mapping!I19="P", 2, Mapping!I19="D", 3, TRUE, "") | J21: =IFS(Mapping!J19="I", 1, Mapping!J19="P", 2, Mapping!J19="D", 3, TRUE, "") | ... M21: =IFS(Mapping!M19="I", 1, Mapping!M19="P", 2, Mapping!M19="D", 3, TRUE, "")
B22: CLO3 | C22: =IFS(Mapping!C20="I", 1, Mapping!C20="P", 2, Mapping!C20="D", 3, TRUE, "") | D22: =IFS(Mapping!D20="I", 1, Mapping!D20="P", 2, Mapping!D20="D", 3, TRUE, "") | E22: =IFS(Mapping!E20="I", 1, Mapping!E20="P", 2, Mapping!E20="D", 3, TRUE, "") -> 2 | F22: =IFS(Mapping!F20="I", 1, Mapping!F20="P", 2, Mapping!F20="D", 3, TRUE, "") | G22: =IFS(Mapping!G20="I", 1, Mapping!G20="P", 2, Mapping!G20="D", 3, TRUE, "") | H22: =IFS(Mapping!H20="I", 1, Mapping!H20="P", 2, Mapping!H20="D", 3, TRUE, "") | I22: =IFS(Mapping!I20="I", 1, Mapping!I20="P", 2, Mapping!I20="D", 3, TRUE, "") | J22: =IFS(Mapping!J20="I", 1, Mapping!J20="P", 2, Mapping!J20="D", 3, TRUE, "") | ... M22: =IFS(Mapping!M20="I", 1, Mapping!M20="P", 2, Mapping!M20="D", 3, TRUE, "")
A23: CCC151 | C23: =SUM(C24:C26) -> 2 | D23: =SUM(D24:D26) -> 2 | E23: =SUM(E24:E26) -> 2 | F23: =SUM(F24:F26) -> 0 | G23: =SUM(G24:G26) -> 0 | H23: =SUM(H24:H26) -> 0 | I23: =SUM(I24:I26) -> 0 | J23: =SUM(J24:J26) -> 0 | ... M23: =SUM(M24:M26) -> 0
B24: CLO1 | C24: =IFS(Mapping!C22="I", 1, Mapping!C22="P", 2, Mapping!C22="D", 3, TRUE, "") -> 2 | D24: =IFS(Mapping!D22="I", 1, Mapping!D22="P", 2, Mapping!D22="D", 3, TRUE, "") | E24: =IFS(Mapping!E22="I", 1, Mapping!E22="P", 2, Mapping!E22="D", 3, TRUE, "") | F24: =IFS(Mapping!F22="I", 1, Mapping!F22="P", 2, Mapping!F22="D", 3, TRUE, "") | G24: =IFS(Mapping!G22="I", 1, Mapping!G22="P", 2, Mapping!G22="D", 3, TRUE, "") | H24: =IFS(Mapping!H22="I", 1, Mapping!H22="P", 2, Mapping!H22="D", 3, TRUE, "") | I24: =IFS(Mapping!I22="I", 1, Mapping!I22="P", 2, Mapping!I22="D", 3, TRUE, "") | J24: =IFS(Mapping!J22="I", 1, Mapping!J22="P", 2, Mapping!J22="D", 3, TRUE, "") | ... M24: =IFS(Mapping!M22="I", 1, Mapping!M22="P", 2, Mapping!M22="D", 3, TRUE, "")
B25: CLO2 | C25: =IFS(Mapping!C23="I", 1, Mapping!C23="P", 2, Mapping!C23="D", 3, TRUE, "") | D25: =IFS(Mapping!D23="I", 1, Mapping!D23="P", 2, Mapping!D23="D", 3, TRUE, "") -> 2 | E25: =IFS(Mapping!E23="I", 1, Mapping!E23="P", 2, Mapping!E23="D", 3, TRUE, "") | F25: =IFS(Mapping!F23="I", 1, Mapping!F23="P", 2, Mapping!F23="D", 3, TRUE, "") | G25: =IFS(Mapping!G23="I", 1, Mapping!G23="P", 2, Mapping!G23="D", 3, TRUE, "") | H25: =IFS(Mapping!H23="I", 1, Mapping!H23="P", 2, Mapping!H23="D", 3, TRUE, "") | I25: =IFS(Mapping!I23="I", 1, Mapping!I23="P", 2, Mapping!I23="D", 3, TRUE, "") | J25: =IFS(Mapping!J23="I", 1, Mapping!J23="P", 2, Mapping!J23="D", 3, TRUE, "") | ... M25: =IFS(Mapping!M23="I", 1, Mapping!M23="P", 2, Mapping!M23="D", 3, TRUE, "")
B26: CLO3 | C26: =IFS(Mapping!C24="I", 1, Mapping!C24="P", 2, Mapping!C24="D", 3, TRUE, "") | D26: =IFS(Mapping!D24="I", 1, Mapping!D24="P", 2, Mapping!D24="D", 3, TRUE, "") | E26: =IFS(Mapping!E24="I", 1, Mapping!E24="P", 2, Mapping!E24="D", 3, TRUE, "") -> 2 | F26: =IFS(Mapping!F24="I", 1, Mapping!F24="P", 2, Mapping!F24="D", 3, TRUE, "") | G26: =IFS(Mapping!G24="I", 1, Mapping!G24="P", 2, Mapping!G24="D", 3, TRUE, "") | H26: =IFS(Mapping!H24="I", 1, Mapping!H24="P", 2, Mapping!H24="D", 3, TRUE, "") | I26: =IFS(Mapping!I24="I", 1, Mapping!I24="P", 2, Mapping!I24="D", 3, TRUE, "") | J26: =IFS(Mapping!J24="I", 1, Mapping!J24="P", 2, Mapping!J24="D", 3, TRUE, "") | ... M26: =IFS(Mapping!M24="I", 1, Mapping!M24="P", 2, Mapping!M24="D", 3, TRUE, "")
A27: CCC181 | C27: =SUM(C28:C30) -> 3 | D27: =SUM(D28:D30) -> 3 | E27: =SUM(E28:E30) -> 3 | F27: =SUM(F28:F30) -> 0 | G27: =SUM(G28:G30) -> 0 | H27: =SUM(H28:H30) -> 0 | I27: =SUM(I28:I30) -> 0 | J27: =SUM(J28:J30) -> 0 | ... M27: =SUM(M28:M30) -> 0
B28: CLO1 | C28: =IFS(Mapping!C26="I", 1, Mapping!C26="P", 2, Mapping!C26="D", 3, TRUE, "") -> 3 | D28: =IFS(Mapping!D26="I", 1, Mapping!D26="P", 2, Mapping!D26="D", 3, TRUE, "") | E28: =IFS(Mapping!E26="I", 1, Mapping!E26="P", 2, Mapping!E26="D", 3, TRUE, "") | F28: =IFS(Mapping!F26="I", 1, Mapping!F26="P", 2, Mapping!F26="D", 3, TRUE, "") | G28: =IFS(Mapping!G26="I", 1, Mapping!G26="P", 2, Mapping!G26="D", 3, TRUE, "") | H28: =IFS(Mapping!H26="I", 1, Mapping!H26="P", 2, Mapping!H26="D", 3, TRUE, "") | I28: =IFS(Mapping!I26="I", 1, Mapping!I26="P", 2, Mapping!I26="D", 3, TRUE, "") | J28: =IFS(Mapping!J26="I", 1, Mapping!J26="P", 2, Mapping!J26="D", 3, TRUE, "") | ... M28: =IFS(Mapping!M26="I", 1, Mapping!M26="P", 2, Mapping!M26="D", 3, TRUE, "")
B29: CLO2 | C29: =IFS(Mapping!C27="I", 1, Mapping!C27="P", 2, Mapping!C27="D", 3, TRUE, "") | D29: =IFS(Mapping!D27="I", 1, Mapping!D27="P", 2, Mapping!D27="D", 3, TRUE, "") -> 3 | E29: =IFS(Mapping!E27="I", 1, Mapping!E27="P", 2, Mapping!E27="D", 3, TRUE, "") | F29: =IFS(Mapping!F27="I", 1, Mapping!F27="P", 2, Mapping!F27="D", 3, TRUE, "") | G29: =IFS(Mapping!G27="I", 1, Mapping!G27="P", 2, Mapping!G27="D", 3, TRUE, "") | H29: =IFS(Mapping!H27="I", 1, Mapping!H27="P", 2, Mapping!H27="D", 3, TRUE, "") | I29: =IFS(Mapping!I27="I", 1, Mapping!I27="P", 2, Mapping!I27="D", 3, TRUE, "") | J29: =IFS(Mapping!J27="I", 1, Mapping!J27="P", 2, Mapping!J27="D", 3, TRUE, "") | ... M29: =IFS(Mapping!M27="I", 1, Mapping!M27="P", 2, Mapping!M27="D", 3, TRUE, "")
B30: CLO3 | C30: =IFS(Mapping!C28="I", 1, Mapping!C28="P", 2, Mapping!C28="D", 3, TRUE, "") | D30: =IFS(Mapping!D28="I", 1, Mapping!D28="P", 2, Mapping!D28="D", 3, TRUE, "") | E30: =IFS(Mapping!E28="I", 1, Mapping!E28="P", 2, Mapping!E28="D", 3, TRUE, "") -> 3 | F30: =IFS(Mapping!F28="I", 1, Mapping!F28="P", 2, Mapping!F28="D", 3, TRUE, "") | G30: =IFS(Mapping!G28="I", 1, Mapping!G28="P", 2, Mapping!G28="D", 3, TRUE, "") | H30: =IFS(Mapping!H28="I", 1, Mapping!H28="P", 2, Mapping!H28="D", 3, TRUE, "") | I30: =IFS(Mapping!I28="I", 1, Mapping!I28="P", 2, Mapping!I28="D", 3, TRUE, "") | J30: =IFS(Mapping!J28="I", 1, Mapping!J28="P", 2, Mapping!J28="D", 3, TRUE, "") | ... M30: =IFS(Mapping!M28="I", 1, Mapping!M28="P", 2, Mapping!M28="D", 3, TRUE, "")
A31: CSC109 | C31: =SUM(C32:C34) -> 0 | D31: =SUM(D32:D34) -> 0 | E31: =SUM(E32:E34) -> 0 | F31: =SUM(F32:F34) -> 0 | G31: =SUM(G32:G34) -> 0 | H31: =SUM(H32:H34) -> 0 | I31: =SUM(I32:I34) -> 0 | J31: =SUM(J32:J34) -> 3 | ... M31: =SUM(M32:M34) -> 9
B32: CLO1 | C32: =IFS(Mapping!C30="I", 1, Mapping!C30="P", 2, Mapping!C30="D", 3, TRUE, "") | D32: =IFS(Mapping!D30="I", 1, Mapping!D30="P", 2, Mapping!D30="D", 3, TRUE, "") | E32: =IFS(Mapping!E30="I", 1, Mapping!E30="P", 2, Mapping!E30="D", 3, TRUE, "") | F32: =IFS(Mapping!F30="I", 1, Mapping!F30="P", 2, Mapping!F30="D", 3, TRUE, "") | G32: =IFS(Mapping!G30="I", 1, Mapping!G30="P", 2, Mapping!G30="D", 3, TRUE, "") | H32: =IFS(Mapping!H30="I", 1, Mapping!H30="P", 2, Mapping!H30="D", 3, TRUE, "") | I32: =IFS(Mapping!I30="I", 1, Mapping!I30="P", 2, Mapping!I30="D", 3, TRUE, "") | J32: =IFS(Mapping!J30="I", 1, Mapping!J30="P", 2, Mapping!J30="D", 3, TRUE, "") -> 3 | ... M32: =IFS(Mapping!M30="I", 1, Mapping!M30="P", 2, Mapping!M30="D", 3, TRUE, "") -> 3
B33: CLO2 | C33: =IFS(Mapping!C31="I", 1, Mapping!C31="P", 2, Mapping!C31="D", 3, TRUE, "") | D33: =IFS(Mapping!D31="I", 1, Mapping!D31="P", 2, Mapping!D31="D", 3, TRUE, "") | E33: =IFS(Mapping!E31="I", 1, Mapping!E31="P", 2, Mapping!E31="D", 3, TRUE, "") | F33: =IFS(Mapping!F31="I", 1, Mapping!F31="P", 2, Mapping!F31="D", 3, TRUE, "") | G33: =IFS(Mapping!G31="I", 1, Mapping!G31="P", 2, Mapping!G31="D", 3, TRUE, "") | H33: =IFS(Mapping!H31="I", 1, Mapping!H31="P", 2, Mapping!H31="D", 3, TRUE, "") | I33: =IFS(Mapping!I31="I", 1, Mapping!I31="P", 2, Mapping!I31="D", 3, TRUE, "") | J33: =IFS(Mapping!J31="I", 1, Mapping!J31="P", 2, Mapping!J31="D", 3, TRUE, "") | ... M33: =IFS(Mapping!M31="I", 1, Mapping!M31="P", 2, Mapping!M31="D", 3, TRUE, "") -> 3
B34: CLO3 | C34: =IFS(Mapping!C32="I", 1, Mapping!C32="P", 2, Mapping!C32="D", 3, TRUE, "") | D34: =IFS(Mapping!D32="I", 1, Mapping!D32="P", 2, Mapping!D32="D", 3, TRUE, "") | E34: =IFS(Mapping!E32="I", 1, Mapping!E32="P", 2, Mapping!E32="D", 3, TRUE, "") | F34: =IFS(Mapping!F32="I", 1, Mapping!F32="P", 2, Mapping!F32="D", 3, TRUE, "") | G34: =IFS(Mapping!G32="I", 1, Mapping!G32="P", 2, Mapping!G32="D", 3, TRUE, "") | H34: =IFS(Mapping!H32="I", 1, Mapping!H32="P", 2, Mapping!H32="D", 3, TRUE, "") | I34: =IFS(Mapping!I32="I", 1, Mapping!I32="P", 2, Mapping!I32="D", 3, TRUE, "") | J34: =IFS(Mapping!J32="I", 1, Mapping!J32="P", 2, Mapping!J32="D", 3, TRUE, "") | ... M34: =IFS(Mapping!M32="I", 1, Mapping!M32="P", 2, Mapping!M32="D", 3, TRUE, "") -> 3
A35: CSC112 | C35: =SUM(C36:C38) -> 0 | D35: =SUM(D36:D38) -> 0 | E35: =SUM(E36:E38) -> 0 | F35: =SUM(F36:F38) -> 1 | G35: =SUM(G36:G38) -> 2 | H35: =SUM(H36:H38) -> 2 | I35: =SUM(I36:I38) -> 0 | J35: =SUM(J36:J38) -> 0 | ... M35: =SUM(M36:M38) -> 0
B36: CLO1 | C36: =IFS(Mapping!C34="I", 1, Mapping!C34="P", 2, Mapping!C34="D", 3, TRUE, "") | D36: =IFS(Mapping!D34="I", 1, Mapping!D34="P", 2, Mapping!D34="D", 3, TRUE, "") | E36: =IFS(Mapping!E34="I", 1, Mapping!E34="P", 2, Mapping!E34="D", 3, TRUE, "") | F36: =IFS(Mapping!F34="I", 1, Mapping!F34="P", 2, Mapping!F34="D", 3, TRUE, "") -> 1 | G36: =IFS(Mapping!G34="I", 1, Mapping!G34="P", 2, Mapping!G34="D", 3, TRUE, "") | H36: =IFS(Mapping!H34="I", 1, Mapping!H34="P", 2, Mapping!H34="D", 3, TRUE, "") | I36: =IFS(Mapping!I34="I", 1, Mapping!I34="P", 2, Mapping!I34="D", 3, TRUE, "") | J36: =IFS(Mapping!J34="I", 1, Mapping!J34="P", 2, Mapping!J34="D", 3, TRUE, "") | ... M36: =IFS(Mapping!M34="I", 1, Mapping!M34="P", 2, Mapping!M34="D", 3, TRUE, "")
B37: CLO2 | C37: =IFS(Mapping!C35="I", 1, Mapping!C35="P", 2, Mapping!C35="D", 3, TRUE, "") | D37: =IFS(Mapping!D35="I", 1, Mapping!D35="P", 2, Mapping!D35="D", 3, TRUE, "") | E37: =IFS(Mapping!E35="I", 1, Mapping!E35="P", 2, Mapping!E35="D", 3, TRUE, "") | F37: =IFS(Mapping!F35="I", 1, Mapping!F35="P", 2, Mapping!F35="D", 3, TRUE, "") | G37: =IFS(Mapping!G35="I", 1, Mapping!G35="P", 2, Mapping!G35="D", 3, TRUE, "") -> 2 | H37: =IFS(Mapping!H35="I", 1, Mapping!H35="P", 2, Mapping!H35="D", 3, TRUE, "") | I37: =IFS(Mapping!I35="I", 1, Mapping!I35="P", 2, Mapping!I35="D", 3, TRUE, "") | J37: =IFS(Mapping!J35="I", 1, Mapping!J35="P", 2, Mapping!J35="D", 3, TRUE, "") | ... M37: =IFS(Mapping!M35="I", 1, Mapping!M35="P", 2, Mapping!M35="D", 3, TRUE, "")
B38: CLO3 | C38: =IFS(Mapping!C36="I", 1, Mapping!C36="P", 2, Mapping!C36="D", 3, TRUE, "") | D38: =IFS(Mapping!D36="I", 1, Mapping!D36="P", 2, Mapping!D36="D", 3, TRUE, "") | E38: =IFS(Mapping!E36="I", 1, Mapping!E36="P", 2, Mapping!E36="D", 3, TRUE, "") | F38: =IFS(Mapping!F36="I", 1, Mapping!F36="P", 2, Mapping!F36="D", 3, TRUE, "") | G38: =IFS(Mapping!G36="I", 1, Mapping!G36="P", 2, Mapping!G36="D", 3, TRUE, "") | H38: =IFS(Mapping!H36="I", 1, Mapping!H36="P", 2, Mapping!H36="D", 3, TRUE, "") -> 2 | I38: =IFS(Mapping!I36="I", 1, Mapping!I36="P", 2, Mapping!I36="D", 3, TRUE, "") | J38: =IFS(Mapping!J36="I", 1, Mapping!J36="P", 2, Mapping!J36="D", 3, TRUE, "") | ... M38: =IFS(Mapping!M36="I", 1, Mapping!M36="P", 2, Mapping!M36="D", 3, TRUE, "")
A39: CSC113 | C39: =SUM(C40:C42) -> 0 | D39: =SUM(D40:D42) -> 0 | E39: =SUM(E40:E42) -> 0 | F39: =SUM(F40:F42) -> 1 | G39: =SUM(G40:G42) -> 2 | H39: =SUM(H40:H42) -> 2 | I39: =SUM(I40:I42) -> 0 | J39: =SUM(J40:J42) -> 0 | ... M39: =SUM(M40:M42) -> 1
B40: CLO1 | C40: =IFS(Mapping!C38="I", 1, Mapping!C38="P", 2, Mapping!C38="D", 3, TRUE, "") | D40: =IFS(Mapping!D38="I", 1, Mapping!D38="P", 2, Mapping!D38="D", 3, TRUE, "") | E40: =IFS(Mapping!E38="I", 1, Mapping!E38="P", 2, Mapping!E38="D", 3, TRUE, "") | F40: =IFS(Mapping!F38="I", 1, Mapping!F38="P", 2, Mapping!F38="D", 3, TRUE, "") -> 1 | G40: =IFS(Mapping!G38="I", 1, Mapping!G38="P", 2, Mapping!G38="D", 3, TRUE, "") | H40: =IFS(Mapping!H38="I", 1, Mapping!H38="P", 2, Mapping!H38="D", 3, TRUE, "") | I40: =IFS(Mapping!I38="I", 1, Mapping!I38="P", 2, Mapping!I38="D", 3, TRUE, "") | J40: =IFS(Mapping!J38="I", 1, Mapping!J38="P", 2, Mapping!J38="D", 3, TRUE, "") | ... M40: =IFS(Mapping!M38="I", 1, Mapping!M38="P", 2, Mapping!M38="D", 3, TRUE, "")
B41: CLO2 | C41: =IFS(Mapping!C39="I", 1, Mapping!C39="P", 2, Mapping!C39="D", 3, TRUE, "") | D41: =IFS(Mapping!D39="I", 1, Mapping!D39="P", 2, Mapping!D39="D", 3, TRUE, "") | E41: =IFS(Mapping!E39="I", 1, Mapping!E39="P", 2, Mapping!E39="D", 3, TRUE, "") | F41: =IFS(Mapping!F39="I", 1, Mapping!F39="P", 2, Mapping!F39="D", 3, TRUE, "") | G41: =IFS(Mapping!G39="I", 1, Mapping!G39="P", 2, Mapping!G39="D", 3, TRUE, "") -> 2 | H41: =IFS(Mapping!H39="I", 1, Mapping!H39="P", 2, Mapping!H39="D", 3, TRUE, "") | I41: =IFS(Mapping!I39="I", 1, Mapping!I39="P", 2, Mapping!I39="D", 3, TRUE, "") | J41: =IFS(Mapping!J39="I", 1, Mapping!J39="P", 2, Mapping!J39="D", 3, TRUE, "") | ... M41: =IFS(Mapping!M39="I", 1, Mapping!M39="P", 2, Mapping!M39="D", 3, TRUE, "") -> 1
B42: CLO3 | C42: =IFS(Mapping!C40="I", 1, Mapping!C40="P", 2, Mapping!C40="D", 3, TRUE, "") | D42: =IFS(Mapping!D40="I", 1, Mapping!D40="P", 2, Mapping!D40="D", 3, TRUE, "") | E42: =IFS(Mapping!E40="I", 1, Mapping!E40="P", 2, Mapping!E40="D", 3, TRUE, "") | F42: =IFS(Mapping!F40="I", 1, Mapping!F40="P", 2, Mapping!F40="D", 3, TRUE, "") | G42: =IFS(Mapping!G40="I", 1, Mapping!G40="P", 2, Mapping!G40="D", 3, TRUE, "") | H42: =IFS(Mapping!H40="I", 1, Mapping!H40="P", 2, Mapping!H40="D", 3, TRUE, "") -> 2 | I42: =IFS(Mapping!I40="I", 1, Mapping!I40="P", 2, Mapping!I40="D", 3, TRUE, "") | J42: =IFS(Mapping!J40="I", 1, Mapping!J40="P", 2, Mapping!J40="D", 3, TRUE, "") | ... M42: =IFS(Mapping!M40="I", 1, Mapping!M40="P", 2, Mapping!M40="D", 3, TRUE, "")
...

Sheet PLO Attainment by Courses
A1: Direct Assessment of Program Learning Outcomes(PLOs)
A2: Batch 2022 to 2025, (Mapping Course-Level Achievements)
A3: Course Code | B3: CLO No. | C3: CLO Attainment | D3: Program Learning Outcome (PLO) | O3: Program Performance
D4: PLO1 | E4: PLO2 | F4: PLO3 | G4: PLO4 | H4: PLO5 | I4: PLO6 | J4: PLO7 | K4: PLO8 | L4: PLO9 | M4: PLO10 | N4: PLO11
A5: All Courses | D5: =IF(MapWeight!C6<>0, SUM(D7:D9, D11:D13, D15:D17, D19:D21, D23:D25, D27:D29, D31:D33, D35:D37, D39:D41, D43:D45, D47:D49, D51:D53, D55:D57, D59:D61, D63:D65, D67:D69, D71:D73, D75:D77, D79:D81, D83:D85, D87:D89, D91:D93, D95:D97, D99:D101, D103:D105, D107:D109, D111:D113, D115:D117)/MapWeight!C6, "") -> 75.399306 | E5: =IF(MapWeight!D6<>0, SUM(E7:E9, E11:E13, E15:E17, E19:E21, E23:E25, E27:E29, E31:E33, E35:E37, E39:E41, E43:E45, E47:E49, E51:E53, E55:E57, E59:E61, E63:E65, E67:E69, E71:E73, E75:E77, E79:E81, E83:E85, E87:E89, E91:E93, E95:E97, E99:E101, E103:E105, E107:E109, E111:E113, E115:E117)/MapWeight!D6, "") -> 73.878205 | F5: =IF(MapWeight!E6<>0, SUM(F7:F9, F11:F13, F15:F17, F19:F21, F23:F25, F27:F29, F31:F33, F35:F37, F39:F41, F43:F45, F47:F49, F51:F53, F55:F57, F59:F61, F63:F65, F67:F69, F71:F73, F75:F77, F79:F81, F83:F85, F87:F89, F91:F93, F95:F97, F99:F101, F103:F105, F107:F109, F111:F113, F115:F117)/MapWeight!E6, "") -> 74.214286 | G5: =IF(MapWeight!F6<>0, SUM(G7:G9, G11:G13, G15:G17, G19:G21, G23:G25, G27:G29, G31:G33, G35:G37, G39:G41, G43:G45, G47:G49, G51:G53, G55:G57, G59:G61, G63:G65, G67:G69, G71:G73, G75:G77, G79:G81, G83:G85, G87:G89, G91:G93, G95:G97, G99:G101, G103:G105, G107:G109, G111:G113, G115:G117)/MapWeight!F6, "") -> 75.124113 | H5: =IF(MapWeight!G6<>0, SUM(H7:H9, H11:H13, H15:H17, H19:H21, H23:H25, H27:H29, H31:H33, H35:H37, H39:H41, H43:H45, H47:H49, H51:H53, H55:H57, H59:H61, H63:H65, H67:H69, H71:H73, H75:H77, H79:H81, H83:H85, H87:H89, H91:H93, H95:H97, H99:H101, H103:H105, H107:H109, H111:H113, H115:H117)/MapWeight!G6, "") -> 73.525641 | I5: =IF(MapWeight!H6<>0, SUM(I7:I9, I11:I13, I15:I17, I19:I21, I23:I25, I27:I29, I31:I33, I35:I37, I39:I41, I43:I45, I47:I49, I51:I53, I55:I57, I59:I61, I63:I65, I67:I69, I71:I73, I75:I77, I79:I81, I83:I85, I87:I89, I91:I93, I95:I97, I99:I101, I103:I105, I107:I109, I111:I113, I115:I117)/MapWeight!H6, "") -> 73.736111 | J5: =IF(MapWeight!I6<>0, SUM(J7:J9, J11:J13, J15:J17, J19:J21, J23:J25, J27:J29, J31:J33, J35:J37, J39:J41, J43:J45, J47:J49, J51:J53, J55:J57, J59:J61, J63:J65, J67:J69, J71:J73, J75:J77, J79:J81, J83:J85, J87:J89, J91:J93, J95:J97, J99:J101, J103:J105, J107:J109, J111:J113, J115:J117)/MapWeight!I6, "") -> 74.4375 | K5: =IF(MapWeight!J6<>0, SUM(K7:K9, K11:K13, K15:K17, K19:K21, K23:K25, K27:K29, K31:K33, K35:K37, K39:K41, K43:K45, K47:K49, K51:K53, K55:K57, K59:K61, K63:K65, K67:K69, K71:K73, K75:K77, K79:K81, K83:K85, K87:K89, K91:K93, K95:K97, K99:K101, K103:K105, K107:K109, K111:K113, K115:K117)/MapWeight!J6, "") -> 74.675926 | ... N5: =IF(MapWeight!M6<>0, SUM(N7:N9, N11:N13, N15:N17, N19:N21, N23:N25, N27:N29, N31:N33, N35:N37, N39:N41, N43:N45, N47:N49, N51:N53, N55:N57, N59:N61, N63:N65, N67:N69, N71:N73, N75:N77, N79:N81, N83:N85, N87:N89, N91:N93, N95:N97, N99:N101, N103:N105, N107:N109, N111:N113, N115:N117)/MapWeight!M6, "") -> 74.301802 | O5: =AVERAGE(D5:N5) -> 74.324839
A6: CCC100 | C6: =AVERAGE(C7:C9) -> 70.833333 | D6: =IF(MapWeight!C7<>0, SUM(D7:D9)/MapWeight!C7, "") -> 70 | E6: =IF(MapWeight!D7<>0, SUM(E7:E9)/MapWeight!D7, "") -> 87.5 | F6: =IF(MapWeight!E7<>0, SUM(F7:F9)/MapWeight!E7, "") -> 72.5 | G6: =IF(MapWeight!F7<>0, SUM(G7:G9)/MapWeight!F7, "") | H6: =IF(MapWeight!G7<>0, SUM(H7:H9)/MapWeight!G7, "") | I6: =IF(MapWeight!H7<>0, SUM(I7:I9)/MapWeight!H7, "") | J6: =IF(MapWeight!I7<>0, SUM(J7:J9)/MapWeight!I7, "") | K6: =IF(MapWeight!J7<>0, SUM(K7:K9)/MapWeight!J7, "") | ... N6: =IF(MapWeight!M7<>0, SUM(N7:N9)/MapWeight!M7, "") | O6: =AVERAGE(D6:N6) -> 76.666667
B7: CLO1 | C7: =CLO_Attainments!C50 -> 55 | D7: =IF(MapWeight!C8<>"", $C$8*MapWeight!C8, "") -> 70 | E7: =IF(MapWeight!D8<>"", $C$8*MapWeight!D8, "") | F7: =IF(MapWeight!E8<>"", $C$8*MapWeight!E8, "") | G7: =IF(MapWeight!F8<>"", $C$8*MapWeight!F8, "") | H7: =IF(MapWeight!G8<>"", $C$8*MapWeight!G8, "") | I7: =IF(MapWeight!H8<>"", $C$8*MapWeight!H8, "") | J7: =IF(MapWeight!I8<>"", $C$8*MapWeight!I8, "") | K7: =IF(MapWeight!J8<>"", $C$8*MapWeight!J8, "") | ... N7: =IF(MapWeight!M8<>"", $C$8*MapWeight!M8, "")
B8: CLO2 | C8: =CLO_Attainments!D50 -> 70 | D8: =IF(MapWeight!C9<>"", $C$9*MapWeight!C9, "") | E8: =IF(MapWeight!D9<>"", $C$9*MapWeight!D9, "") -> 87.5 | F8: =IF(MapWeight!E9<>"", $C$9*MapWeight!E9, "") | G8: =IF(MapWeight!F9<>"", $C$9*MapWeight!F9, "") | H8: =IF(MapWeight!G9<>"", $C$9*MapWeight!G9, "") | I8: =IF(MapWeight!H9<>"", $C$9*MapWeight!H9, "") | J8: =IF(MapWeight!I9<>"", $C$9*MapWeight!I9, "") | K8: =IF(MapWeight!J9<>"", $C$9*MapWeight!J9, "") | ... N8: =IF(MapWeight!M9<>"", $C$9*MapWeight!M9, "")
B9: CLO3 | C9: =CLO_Attainments!E50 -> 87.5 | D9: =IF(MapWeight!C10<>"", $C$10*MapWeight!C10, "") | E9: =IF(MapWeight!D10<>"", $C$10*MapWeight!D10, "") | F9: =IF(MapWeight!E10<>"", $C$10*MapWeight!E10, "") -> 72.5 | G9: =IF(MapWeight!F10<>"", $C$10*MapWeight!F10, "") | H9: =IF(MapWeight!G10<>"", $C$10*MapWeight!G10, "") | I9: =IF(MapWeight!H10<>"", $C$10*MapWeight!H10, "") | J9: =IF(MapWeight!I10<>"", $C$10*MapWeight!I10, "") | K9: =IF(MapWeight!J10<>"", $C$10*MapWeight!J10, "") | ... N9: =IF(MapWeight!M10<>"", $C$10*MapWeight!M10, "")
A10: CCC101 | C10: =AVERAGE(C11:C13) -> 72.5 | D10: =IF(MapWeight!C11<>0, SUM(D11:D13)/MapWeight!C11, "") -> 67.5 | E10: =IF(MapWeight!D11<>0, SUM(E11:E13)/MapWeight!D11, "") -> 80 | F10: =IF(MapWeight!E11<>0, SUM(F11:F13)/MapWeight!E11, "") -> 71.666667 | G10: =IF(MapWeight!F11<>0, SUM(G11:G13)/MapWeight!F11, "") | H10: =IF(MapWeight!G11<>0, SUM(H11:H13)/MapWeight!G11, "") | I10: =IF(MapWeight!H11<>0, SUM(I11:I13)/MapWeight!H11, "") | J10: =IF(MapWeight!I11<>0, SUM(J11:J13)/MapWeight!I11, "") | K10: =IF(MapWeight!J11<>0, SUM(K11:K13)/MapWeight!J11, "") | ... N10: =IF(MapWeight!M11<>0, SUM(N11:N13)/MapWeight!M11, "") | O10: =AVERAGE(D10:N10) -> 73.055556
B11: CLO1 | C11: =CLO_Attainments!F50 -> 70 | D11: =IF(MapWeight!C12<>"", $C$12*MapWeight!C12, "") -> 67.5 | E11: =IF(MapWeight!D12<>"", $C$12*MapWeight!D12, "") | F11: =IF(MapWeight!E12<>"", $C$12*MapWeight!E12, "") | G11: =IF(MapWeight!F12<>"", $C$12*MapWeight!F12, "") | H11: =IF(MapWeight!G12<>"", $C$12*MapWeight!G12, "") | I11: =IF(MapWeight!H12<>"", $C$12*MapWeight!H12, "") | J11: =IF(MapWeight!I12<>"", $C$12*MapWeight!I12, "") | K11: =IF(MapWeight!J12<>"", $C$12*MapWeight!J12, "") | ... N11: =IF(MapWeight!M12<>"", $C$12*MapWeight!M12, "")
B12: CLO2 | C12: =CLO_Attainments!G50 -> 67.5 | D12: =IF(MapWeight!C13<>"", $C$13*MapWeight!C13, "") | E12: =IF(MapWeight!D13<>"", $C$13*MapWeight!D13, "") -> 80 | F12: =IF(MapWeight!E13<>"", $C$13*MapWeight!E13, "") | G12: =IF(MapWeight!F13<>"", $C$13*MapWeight!F13, "") | H12: =IF(MapWeight!G13<>"", $C$13*MapWeight!G13, "") | I12: =IF(MapWeight!H13<>"", $C$13*MapWeight!H13, "") | J12: =IF(MapWeight!I13<>"", $C$13*MapWeight!I13, "") | K12: =IF(MapWeight!J13<>"", $C$13*MapWeight!J13, "") | ... N12: =IF(MapWeight!M13<>"", $C$13*MapWeight!M13, "")
B13: CLO3 | C13: =CLO_Attainments!H50 -> 80 | D13: =IF(MapWeight!C14<>"", $C$14*MapWeight!C14, "") | E13: =IF(MapWeight!D14<>"", $C$14*MapWeight!D14, "") | F13: =IF(MapWeight!E14<>"", $C$14*MapWeight!E14, "") -> 71.666667 | G13: =IF(MapWeight!F14<>"", $C$14*MapWeight!F14, "") | H13: =IF(MapWeight!G14<>"", $C$14*MapWeight!G14, "") | I13: =IF(MapWeight!H14<>"", $C$14*MapWeight!H14, "") | J13: =IF(MapWeight!I14<>"", $C$14*MapWeight!I14, "") | K13: =IF(MapWeight!J14<>"", $C$14*MapWeight!J14, "") | ... N13: =IF(MapWeight!M14<>"", $C$14*MapWeight!M14, "")
A14: CCC102 | C14: =AVERAGE(C15:C17) -> 71.666667 | D14: =IF(MapWeight!C15<>0, SUM(D15:D17)/MapWeight!C15, "") -> 67.5 | E14: =IF(MapWeight!D15<>0, SUM(E15:E17)/MapWeight!D15, "") -> 70 | F14: =IF(MapWeight!E15<>0, SUM(F15:F17)/MapWeight!E15, "") -> 74.166667 | G14: =IF(MapWeight!F15<>0, SUM(G15:G17)/MapWeight!F15, "") | H14: =IF(MapWeight!G15<>0, SUM(H15:H17)/MapWeight!G15, "") | I14: =IF(MapWeight!H15<>0, SUM(I15:I17)/MapWeight!H15, "") | J14: =IF(MapWeight!I15<>0, SUM(J15:J17)/MapWeight!I15, "") | K14: =IF(MapWeight!J15<>0, SUM(K15:K17)/MapWeight!J15, "") | ... N14: =IF(MapWeight!M15<>0, SUM(N15:N17)/MapWeight!M15, "") | O14: =AVERAGE(D14:N14) -> 70.555556
B15: CLO1 | C15: =CLO_Attainments!I50 -> 77.5 | D15: =IF(MapWeight!C16<>"", $C$16*MapWeight!C16, "") -> 67.5 | E15: =IF(MapWeight!D16<>"", $C$16*MapWeight!D16, "") | F15: =IF(MapWeight!E16<>"", $C$16*MapWeight!E16, "") | G15: =IF(MapWeight!F16<>"", $C$16*MapWeight!F16, "") | H15: =IF(MapWeight!G16<>"", $C$16*MapWeight!G16, "") | I15: =IF(MapWeight!H16<>"", $C$16*MapWeight!H16, "") | J15: =IF(MapWeight!I16<>"", $C$16*MapWeight!I16, "") | K15: =IF(MapWeight!J16<>"", $C$16*MapWeight!J16, "") | ... N15: =IF(MapWeight!M16<>"", $C$16*MapWeight!M16, "")
B16: CLO2 | C16: =CLO_Attainments!J50 -> 67.5 | D16: =IF(MapWeight!C17<>"", $C$17*MapWeight!C17, "") | E16: =IF(MapWeight!D17<>"", $C$17*MapWeight!D17, "") -> 70 | F16: =IF(MapWeight!E17<>"", $C$17*MapWeight!E17, "") | G16: =IF(MapWeight!F17<>"", $C$17*MapWeight!F17, "") | H16: =IF(MapWeight!G17<>"", $C$17*MapWeight!G17, "") | I16: =IF(MapWeight!H17<>"", $C$17*MapWeight!H17, "") | J16: =IF(MapWeight!I17<>"", $C$17*MapWeight!I17, "") | K16: =IF(MapWeight!J17<>"", $C$17*MapWeight!J17, "") | ... N16: =IF(MapWeight!M17<>"", $C$17*MapWeight!M17, "")
B17: CLO3 | C17: =CLO_Attainments!K50 -> 70 | D17: =IF(MapWeight!C18<>"", $C$18*MapWeight!C18, "") | E17: =IF(MapWeight!D18<>"", $C$18*MapWeight!D18, "") | F17: =IF(MapWeight!E18<>"", $C$18*MapWeight!E18, "") -> 74.166667 | G17: =IF(MapWeight!F18<>"", $C$18*MapWeight!F18, "") | H17: =IF(MapWeight!G18<>"", $C$18*MapWeight!G18, "") | I17: =IF(MapWeight!H18<>"", $C$18*MapWeight!H18, "") | J17: =IF(MapWeight!I18<>"", $C$18*MapWeight!I18, "") | K17: =IF(MapWeight!J18<>"", $C$18*MapWeight!J18, "") | ... N17: =IF(MapWeight!M18<>"", $C$18*MapWeight!M18, "")
A18: CCC121 | C18: =AVERAGE(C19:C21) -> 74.166667 | D18: =IF(MapWeight!C19<>0, SUM(D19:D21)/MapWeight!C19, "") -> 77.5 | E18: =IF(MapWeight!D19<>0, SUM(E19:E21)/MapWeight!D19, "") -> 72.5 | F18: =IF(MapWeight!E19<>0, SUM(F19:F21)/MapWeight!E19, "") -> 73.333333 | G18: =IF(MapWeight!F19<>0, SUM(G19:G21)/MapWeight!F19, "") | H18: =IF(MapWeight!G19<>0, SUM(H19:H21)/MapWeight!G19, "") | I18: =IF(MapWeight!H19<>0, SUM(I19:I21)/MapWeight!H19, "") | J18: =IF(MapWeight!I19<>0, SUM(J19:J21)/MapWeight!I19, "") | K18: =IF(MapWeight!J19<>0, SUM(K19:K21)/MapWeight!J19, "") | ... N18: =IF(MapWeight!M19<>0, SUM(N19:N21)/MapWeight!M19, "") | O18: =AVERAGE(D18:N18) -> 74.444444
B19: CLO1 | C19: =CLO_Attainments!L50 -> 72.5 | D19: =IF(MapWeight!C20<>"", $C$20*MapWeight!C20, "") -> 155 | E19: =IF(MapWeight!D20<>"", $C$20*MapWeight!D20, "") | F19: =IF(MapWeight!E20<>"", $C$20*MapWeight!E20, "") | G19: =IF(MapWeight!F20<>"", $C$20*MapWeight!F20, "") | H19: =IF(MapWeight!G20<>"", $C$20*MapWeight!G20, "") | I19: =IF(MapWeight!H20<>"", $C$20*MapWeight!H20, "") | J19: =IF(MapWeight!I20<>"", $C$20*MapWeight!I20, "") | K19: =IF(MapWeight!J20<>"", $C$20*MapWeight!J20, "") | ... N19: =IF(MapWeight!M20<>"", $C$20*MapWeight!M20, "")
B20: CLO2 | C20: =CLO_Attainments!M50 -> 77.5 | D20: =IF(MapWeight!C21<>"", $C$21*MapWeight!C21, "") | E20: =IF(MapWeight!D21<>"", $C$21*MapWeight!D21, "") -> 145 | F20: =IF(MapWeight!E21<>"", $C$21*MapWeight!E21, "") | G20: =IF(MapWeight!F21<>"", $C$21*MapWeight!F21, "") | H20: =IF(MapWeight!G21<>"", $C$21*MapWeight!G21, "") | I20: =IF(MapWeight!H21<>"", $C$21*MapWeight!H21, "") | J20: =IF(MapWeight!I21<>"", $C$21*MapWeight!I21, "") | K20: =IF(MapWeight!J21<>"", $C$21*MapWeight!J21, "") | ... N20: =IF(MapWeight!M21<>"", $C$21*MapWeight!M21, "")
B21: CLO3 | C21: =CLO_Attainments!N50 -> 72.5 | D21: =IF(MapWeight!C22<>"", $C$22*MapWeight!C22, "") | E21: =IF(MapWeight!D22<>"", $C$22*MapWeight!D22, "") | F21: =IF(MapWeight!E22<>"", $C$22*MapWeight!E22, "") -> 146.66667 | G21: =IF(MapWeight!F22<>"", $C$22*MapWeight!F22, "") | H21: =IF(MapWeight!G22<>"", $C$22*MapWeight!G22, "") | I21: =IF(MapWeight!H22<>"", $C$22*MapWeight!H22, "") | J21: =IF(MapWeight!I22<>"", $C$22*MapWeight!I22, "") | K21: =IF(MapWeight!J22<>"", $C$22*MapWeight!J22, "") | ... N21: =IF(MapWeight!M22<>"", $C$22*MapWeight!M22, "")
A22: CCC151 | C22: =AVERAGE(C23:C25) -> 73.333333 | D22: =IF(MapWeight!C23<>0, SUM(D23:D25)/MapWeight!C23, "") -> 77.5 | E22: =IF(MapWeight!D23<>0, SUM(E23:E25)/MapWeight!D23, "") -> 72.5 | F22: =IF(MapWeight!E23<>0, SUM(F23:F25)/MapWeight!E23, "") -> 73.333333 | G22: =IF(MapWeight!F23<>0, SUM(G23:G25)/MapWeight!F23, "") | H22: =IF(MapWeight!G23<>0, SUM(H23:H25)/MapWeight!G23, "") | I22: =IF(MapWeight!H23<>0, SUM(I23:I25)/MapWeight!H23, "") | J22: =IF(MapWeight!I23<>0, SUM(J23:J25)/MapWeight!I23, "") | K22: =IF(MapWeight!J23<>0, SUM(K23:K25)/MapWeight!J23, "") | ... N22: =IF(MapWeight!M23<>0, SUM(N23:N25)/MapWeight!M23, "") | O22: =AVERAGE(D22:N22) -> 74.444444
B23: CLO1 | C23: =CLO_Attainments!O50 -> 75 | D23: =IF(MapWeight!C24<>"", $C$20*MapWeight!C24, "") -> 155 | E23: =IF(MapWeight!D24<>"", $C$20*MapWeight!D24, "") | F23: =IF(MapWeight!E24<>"", $C$20*MapWeight!E24, "") | G23: =IF(MapWeight!F24<>"", $C$20*MapWeight!F24, "") | H23: =IF(MapWeight!G24<>"", $C$20*MapWeight!G24, "") | I23: =IF(MapWeight!H24<>"", $C$20*MapWeight!H24, "") | J23: =IF(MapWeight!I24<>"", $C$20*MapWeight!I24, "") | K23: =IF(MapWeight!J24<>"", $C$20*MapWeight!J24, "") | ... N23: =IF(MapWeight!M24<>"", $C$20*MapWeight!M24, "")
B24: CLO2 | C24: =CLO_Attainments!P50 -> 72.5 | D24: =IF(MapWeight!C25<>"", $C$21*MapWeight!C25, "") | E24: =IF(MapWeight!D25<>"", $C$21*MapWeight!D25, "") -> 145 | F24: =IF(MapWeight!E25<>"", $C$21*MapWeight!E25, "") | G24: =IF(MapWeight!F25<>"", $C$21*MapWeight!F25, "") | H24: =IF(MapWeight!G25<>"", $C$21*MapWeight!G25, "") | I24: =IF(MapWeight!H25<>"", $C$21*MapWeight!H25, "") | J24: =IF(MapWeight!I25<>"", $C$21*MapWeight!I25, "") | K24: =IF(MapWeight!J25<>"", $C$21*MapWeight!J25, "") | ... N24: =IF(MapWeight!M25<>"", $C$21*MapWeight!M25, "")
